[2021-11-17 23:53:33,204] {taskinstance.py:1035} INFO - Dependencies all met for <TaskInstance: example_ML_pipeline_DAG.scoring_task manual__2021-11-18T07:53:26.082952+00:00 [queued]>
[2021-11-17 23:53:33,208] {taskinstance.py:1035} INFO - Dependencies all met for <TaskInstance: example_ML_pipeline_DAG.scoring_task manual__2021-11-18T07:53:26.082952+00:00 [queued]>
[2021-11-17 23:53:33,208] {taskinstance.py:1241} INFO - 
--------------------------------------------------------------------------------
[2021-11-17 23:53:33,208] {taskinstance.py:1242} INFO - Starting attempt 1 of 1
[2021-11-17 23:53:33,208] {taskinstance.py:1243} INFO - 
--------------------------------------------------------------------------------
[2021-11-17 23:53:33,212] {taskinstance.py:1262} INFO - Executing <Task(BashOperator): scoring_task> on 2021-11-18 07:53:26.082952+00:00
[2021-11-17 23:53:33,216] {standard_task_runner.py:52} INFO - Started process 54101 to run task
[2021-11-17 23:53:33,220] {standard_task_runner.py:76} INFO - Running: ['airflow', 'tasks', 'run', 'example_ML_pipeline_DAG', 'scoring_task', 'manual__2021-11-18T07:53:26.082952+00:00', '--job-id', '4', '--raw', '--subdir', 'DAGS_FOLDER/SampleDag.py', '--cfg-path', '/var/folders/ts/0394s80n0mq8hyr7msfqdwnh0000gn/T/tmpi1f9kufj', '--error-file', '/var/folders/ts/0394s80n0mq8hyr7msfqdwnh0000gn/T/tmpae07y96k']
[2021-11-17 23:53:33,222] {standard_task_runner.py:77} INFO - Job 4: Subtask scoring_task
[2021-11-17 23:53:33,242] {logging_mixin.py:109} INFO - Running <TaskInstance: example_ML_pipeline_DAG.scoring_task manual__2021-11-18T07:53:26.082952+00:00 [running]> on host 1.0.0.0.0.0.0.0.0.0.0.0.0.0.0.0.0.0.0.0.0.0.0.0.0.0.0.0.0.0.0.0.ip6.arpa
[2021-11-17 23:53:33,260] {taskinstance.py:1427} INFO - Exporting the following env vars:
AIRFLOW_CTX_DAG_OWNER=airflow
AIRFLOW_CTX_DAG_ID=example_ML_pipeline_DAG
AIRFLOW_CTX_TASK_ID=scoring_task
AIRFLOW_CTX_EXECUTION_DATE=2021-11-18T07:53:26.082952+00:00
AIRFLOW_CTX_DAG_RUN_ID=manual__2021-11-18T07:53:26.082952+00:00
[2021-11-17 23:53:33,260] {subprocess.py:62} INFO - Tmp dir root location: 
 /var/folders/ts/0394s80n0mq8hyr7msfqdwnh0000gn/T
[2021-11-17 23:53:33,261] {subprocess.py:74} INFO - Running command: ['bash', '-c', 'python ~/PycharmProjects/Airflow.py']
[2021-11-17 23:53:33,268] {subprocess.py:85} INFO - Output:
[2021-11-17 23:53:33,310] {subprocess.py:89} INFO - /Users/sravanisigadam/PycharmProjects/Airflow/venv/bin/python: can't open file '/Users/sravanisigadam/PycharmProjects/Airflow.py': [Errno 2] No such file or directory
[2021-11-17 23:53:33,313] {subprocess.py:93} INFO - Command exited with return code 2
[2021-11-17 23:53:33,319] {taskinstance.py:1703} ERROR - Task failed with exception
Traceback (most recent call last):
  File "/Users/sravanisigadam/PycharmProjects/Airflow/venv/lib/python3.9/site-packages/airflow/models/taskinstance.py", line 1332, in _run_raw_task
    self._execute_task_with_callbacks(context)
  File "/Users/sravanisigadam/PycharmProjects/Airflow/venv/lib/python3.9/site-packages/airflow/models/taskinstance.py", line 1458, in _execute_task_with_callbacks
    result = self._execute_task(context, self.task)
  File "/Users/sravanisigadam/PycharmProjects/Airflow/venv/lib/python3.9/site-packages/airflow/models/taskinstance.py", line 1514, in _execute_task
    result = execute_callable(context=context)
  File "/Users/sravanisigadam/PycharmProjects/Airflow/venv/lib/python3.9/site-packages/airflow/operators/bash.py", line 187, in execute
    raise AirflowException(
airflow.exceptions.AirflowException: Bash command failed. The command returned a non-zero exit code 2.
[2021-11-17 23:53:33,325] {taskinstance.py:1270} INFO - Marking task as FAILED. dag_id=example_ML_pipeline_DAG, task_id=scoring_task, execution_date=20211118T075326, start_date=20211118T075333, end_date=20211118T075333
[2021-11-17 23:53:33,331] {standard_task_runner.py:88} ERROR - Failed to execute job 4 for task scoring_task
Traceback (most recent call last):
  File "/Users/sravanisigadam/PycharmProjects/Airflow/venv/lib/python3.9/site-packages/airflow/task/task_runner/standard_task_runner.py", line 85, in _start_by_fork
    args.func(args, dag=self.dag)
  File "/Users/sravanisigadam/PycharmProjects/Airflow/venv/lib/python3.9/site-packages/airflow/cli/cli_parser.py", line 48, in command
    return func(*args, **kwargs)
  File "/Users/sravanisigadam/PycharmProjects/Airflow/venv/lib/python3.9/site-packages/airflow/utils/cli.py", line 92, in wrapper
    return f(*args, **kwargs)
  File "/Users/sravanisigadam/PycharmProjects/Airflow/venv/lib/python3.9/site-packages/airflow/cli/commands/task_command.py", line 292, in task_run
    _run_task_by_selected_method(args, dag, ti)
  File "/Users/sravanisigadam/PycharmProjects/Airflow/venv/lib/python3.9/site-packages/airflow/cli/commands/task_command.py", line 107, in _run_task_by_selected_method
    _run_raw_task(args, ti)
  File "/Users/sravanisigadam/PycharmProjects/Airflow/venv/lib/python3.9/site-packages/airflow/cli/commands/task_command.py", line 180, in _run_raw_task
    ti._run_raw_task(
  File "/Users/sravanisigadam/PycharmProjects/Airflow/venv/lib/python3.9/site-packages/airflow/utils/session.py", line 70, in wrapper
    return func(*args, session=session, **kwargs)
  File "/Users/sravanisigadam/PycharmProjects/Airflow/venv/lib/python3.9/site-packages/airflow/models/taskinstance.py", line 1332, in _run_raw_task
    self._execute_task_with_callbacks(context)
  File "/Users/sravanisigadam/PycharmProjects/Airflow/venv/lib/python3.9/site-packages/airflow/models/taskinstance.py", line 1458, in _execute_task_with_callbacks
    result = self._execute_task(context, self.task)
  File "/Users/sravanisigadam/PycharmProjects/Airflow/venv/lib/python3.9/site-packages/airflow/models/taskinstance.py", line 1514, in _execute_task
    result = execute_callable(context=context)
  File "/Users/sravanisigadam/PycharmProjects/Airflow/venv/lib/python3.9/site-packages/airflow/operators/bash.py", line 187, in execute
    raise AirflowException(
airflow.exceptions.AirflowException: Bash command failed. The command returned a non-zero exit code 2.
[2021-11-17 23:53:33,373] {local_task_job.py:154} INFO - Task exited with return code 1
[2021-11-17 23:53:33,383] {local_task_job.py:264} INFO - 0 downstream tasks scheduled from follow-on schedule check
