[2021-11-17 23:51:59,395] {taskinstance.py:1035} INFO - Dependencies all met for <TaskInstance: example_ML_pipeline_DAG.training_task manual__2021-11-18T07:51:57.525527+00:00 [queued]>
[2021-11-17 23:51:59,400] {taskinstance.py:1035} INFO - Dependencies all met for <TaskInstance: example_ML_pipeline_DAG.training_task manual__2021-11-18T07:51:57.525527+00:00 [queued]>
[2021-11-17 23:51:59,400] {taskinstance.py:1241} INFO - 
--------------------------------------------------------------------------------
[2021-11-17 23:51:59,400] {taskinstance.py:1242} INFO - Starting attempt 1 of 1
[2021-11-17 23:51:59,400] {taskinstance.py:1243} INFO - 
--------------------------------------------------------------------------------
[2021-11-17 23:51:59,406] {taskinstance.py:1262} INFO - Executing <Task(BashOperator): training_task> on 2021-11-18 07:51:57.525527+00:00
[2021-11-17 23:51:59,410] {standard_task_runner.py:52} INFO - Started process 54040 to run task
[2021-11-17 23:51:59,418] {standard_task_runner.py:76} INFO - Running: ['airflow', 'tasks', 'run', 'example_ML_pipeline_DAG', 'training_task', 'manual__2021-11-18T07:51:57.525527+00:00', '--job-id', '2', '--raw', '--subdir', 'DAGS_FOLDER/SampleDag.py', '--cfg-path', '/var/folders/ts/0394s80n0mq8hyr7msfqdwnh0000gn/T/tmpuba09eti', '--error-file', '/var/folders/ts/0394s80n0mq8hyr7msfqdwnh0000gn/T/tmpphetl1b1']
[2021-11-17 23:51:59,420] {standard_task_runner.py:77} INFO - Job 2: Subtask training_task
[2021-11-17 23:51:59,446] {logging_mixin.py:109} INFO - Running <TaskInstance: example_ML_pipeline_DAG.training_task manual__2021-11-18T07:51:57.525527+00:00 [running]> on host 1.0.0.0.0.0.0.0.0.0.0.0.0.0.0.0.0.0.0.0.0.0.0.0.0.0.0.0.0.0.0.0.ip6.arpa
[2021-11-17 23:51:59,464] {taskinstance.py:1427} INFO - Exporting the following env vars:
AIRFLOW_CTX_DAG_OWNER=airflow
AIRFLOW_CTX_DAG_ID=example_ML_pipeline_DAG
AIRFLOW_CTX_TASK_ID=training_task
AIRFLOW_CTX_EXECUTION_DATE=2021-11-18T07:51:57.525527+00:00
AIRFLOW_CTX_DAG_RUN_ID=manual__2021-11-18T07:51:57.525527+00:00
[2021-11-17 23:51:59,464] {subprocess.py:62} INFO - Tmp dir root location: 
 /var/folders/ts/0394s80n0mq8hyr7msfqdwnh0000gn/T
[2021-11-17 23:51:59,465] {subprocess.py:74} INFO - Running command: ['bash', '-c', 'python ModelScript.py']
[2021-11-17 23:51:59,480] {subprocess.py:85} INFO - Output:
[2021-11-17 23:51:59,540] {subprocess.py:89} INFO - /Users/sravanisigadam/PycharmProjects/Airflow/venv/bin/python: can't open file '/private/var/folders/ts/0394s80n0mq8hyr7msfqdwnh0000gn/T/airflowtmp6_j6at7u/ModelScript.py': [Errno 2] No such file or directory
[2021-11-17 23:51:59,543] {subprocess.py:93} INFO - Command exited with return code 2
[2021-11-17 23:51:59,549] {taskinstance.py:1703} ERROR - Task failed with exception
Traceback (most recent call last):
  File "/Users/sravanisigadam/PycharmProjects/Airflow/venv/lib/python3.9/site-packages/airflow/models/taskinstance.py", line 1332, in _run_raw_task
    self._execute_task_with_callbacks(context)
  File "/Users/sravanisigadam/PycharmProjects/Airflow/venv/lib/python3.9/site-packages/airflow/models/taskinstance.py", line 1458, in _execute_task_with_callbacks
    result = self._execute_task(context, self.task)
  File "/Users/sravanisigadam/PycharmProjects/Airflow/venv/lib/python3.9/site-packages/airflow/models/taskinstance.py", line 1514, in _execute_task
    result = execute_callable(context=context)
  File "/Users/sravanisigadam/PycharmProjects/Airflow/venv/lib/python3.9/site-packages/airflow/operators/bash.py", line 187, in execute
    raise AirflowException(
airflow.exceptions.AirflowException: Bash command failed. The command returned a non-zero exit code 2.
[2021-11-17 23:51:59,554] {taskinstance.py:1270} INFO - Marking task as FAILED. dag_id=example_ML_pipeline_DAG, task_id=training_task, execution_date=20211118T075157, start_date=20211118T075159, end_date=20211118T075159
[2021-11-17 23:51:59,560] {standard_task_runner.py:88} ERROR - Failed to execute job 2 for task training_task
Traceback (most recent call last):
  File "/Users/sravanisigadam/PycharmProjects/Airflow/venv/lib/python3.9/site-packages/airflow/task/task_runner/standard_task_runner.py", line 85, in _start_by_fork
    args.func(args, dag=self.dag)
  File "/Users/sravanisigadam/PycharmProjects/Airflow/venv/lib/python3.9/site-packages/airflow/cli/cli_parser.py", line 48, in command
    return func(*args, **kwargs)
  File "/Users/sravanisigadam/PycharmProjects/Airflow/venv/lib/python3.9/site-packages/airflow/utils/cli.py", line 92, in wrapper
    return f(*args, **kwargs)
  File "/Users/sravanisigadam/PycharmProjects/Airflow/venv/lib/python3.9/site-packages/airflow/cli/commands/task_command.py", line 292, in task_run
    _run_task_by_selected_method(args, dag, ti)
  File "/Users/sravanisigadam/PycharmProjects/Airflow/venv/lib/python3.9/site-packages/airflow/cli/commands/task_command.py", line 107, in _run_task_by_selected_method
    _run_raw_task(args, ti)
  File "/Users/sravanisigadam/PycharmProjects/Airflow/venv/lib/python3.9/site-packages/airflow/cli/commands/task_command.py", line 180, in _run_raw_task
    ti._run_raw_task(
  File "/Users/sravanisigadam/PycharmProjects/Airflow/venv/lib/python3.9/site-packages/airflow/utils/session.py", line 70, in wrapper
    return func(*args, session=session, **kwargs)
  File "/Users/sravanisigadam/PycharmProjects/Airflow/venv/lib/python3.9/site-packages/airflow/models/taskinstance.py", line 1332, in _run_raw_task
    self._execute_task_with_callbacks(context)
  File "/Users/sravanisigadam/PycharmProjects/Airflow/venv/lib/python3.9/site-packages/airflow/models/taskinstance.py", line 1458, in _execute_task_with_callbacks
    result = self._execute_task(context, self.task)
  File "/Users/sravanisigadam/PycharmProjects/Airflow/venv/lib/python3.9/site-packages/airflow/models/taskinstance.py", line 1514, in _execute_task
    result = execute_callable(context=context)
  File "/Users/sravanisigadam/PycharmProjects/Airflow/venv/lib/python3.9/site-packages/airflow/operators/bash.py", line 187, in execute
    raise AirflowException(
airflow.exceptions.AirflowException: Bash command failed. The command returned a non-zero exit code 2.
[2021-11-17 23:51:59,570] {local_task_job.py:154} INFO - Task exited with return code 1
[2021-11-17 23:51:59,583] {local_task_job.py:264} INFO - 0 downstream tasks scheduled from follow-on schedule check
